<?xml version="1.0" ?>
<robot name="moby">
  <material name="black">
    <color rgba="0.0 0.0 0.0 1.0"/>
  </material>
  <material name="blue">
    <color rgba="0.0 0.0 0.8 1.0"/>
  </material>
  <material name="green">
    <color rgba="0.0 0.8 0.0 1.0"/>
  </material>
  <material name="icon_green">
    <color rgba="0.596078431372549 0.7764705882352941 0.3843137254901961 1.0"/>
  </material>
  <material name="icon_grey">
    <color rgba="0.2 0.2 0.2 1.0"/>
  </material>
  <material name="indy_white">
    <color rgba="0.8941176470588236 0.8941176470588236 0.8941176470588236 1.0"/>
  </material>
  <material name="grey">
    <color rgba="0.2 0.2 0.2 1.0"/>
  </material>
  <material name="orange">
    <color rgba="1.0 0.4235294117647059 0.0392156862745098 1.0"/>
  </material>
  <material name="brown">
    <color rgba="0.8705882352941177 0.8117647058823529 0.7647058823529411 1.0"/>
  </material>
  <material name="red">
    <color rgba="0.8 0.0 0.0 1.0"/>
  </material>
  <material name="white">
    <color rgba="1.0 1.0 1.0 1.0"/>
  </material>
  <material name="metal">
    <color rgba="0.768627450980392 0.749019607843137 0.729411764705882 1"/>
  </material>
  <material name="metal_grey">
    <color rgba="0.501960784313725 0.501960784313725 0.501960784313725 1"/>
  </material>
  <material name="metal_white">
    <color rgba="0.866666666666667 0.866666666666667 0.890196078431373 1"/>
  </material>
  <material name="aluminum">
    <color rgba="0.5 0.5 0.5 1.0"/>
  </material>
  <!-- <xacro:include filename="$(find realsense2_description)/urdf/_d415.urdf.xacro" />
    <xacro:include filename="$(find realsense2_description)/urdf/_d435.urdf.xacro" /> -->
  <!-- LINKS -->
  <!-- <xacro:define_link link_name="base_footprint"  physic_name="base_footprint" visual_name="" material=""/>
        <xacro:define_link link_name="base_link"  physic_name="base_link" visual_name="" material=""/> -->
  <link name="base_footprint"/>
  <link name="base_link"/>
  <link name="imu_link"/>
  <!-- Moby Agri -->
  <!-- <xacro:if value="${moby_type == 'moby_agri'}">
            <xacro:robot_link prefix="${prefix}" link_index="right_tract_link"   material="${wheel_material}" mesh_name="moby_wheel"/>
            <xacro:robot_link prefix="${prefix}" link_index="left_tract_link"    material="${wheel_material}" mesh_name="moby_wheel"/>
            <xacro:robot_link prefix="${prefix}" link_index="camera_module_link" material="${indy_material}"  mesh_name="camera_module"/>
        </xacro:if> -->
  <link name="top_frame">
    <visual>
      <origin rpy="0 0 0" xyz="0 0 0"/>
      <geometry>
        <mesh filename="moby_rp/visual/Top_frame.stl"/>
      </geometry>
      <material name="metal_white"/>
    </visual>
    <collision>
      <origin rpy="0 0 0" xyz="0 0 0"/>
      <geometry>
        <mesh filename="moby_rp/collision/Top_frame.stl"/>
      </geometry>
    </collision>
    <inertial>
      <mass value="26.877"/>
      <origin rpy="0 0 0" xyz="-0.001287                             -8.9e-05                             0.028821"/>
      <inertia ixx="1.010559" ixy="-3e-06" ixz="0.000997" iyy="2.444044" iyz="6.9e-05" izz="3.046105"/>
    </inertial>
    <surface>
      <friction>
        <ode>
          <mu>0.8</mu>
          <mu2>0.8</mu2>
          <kp>1e15</kp>
          <kd>1e13</kd>
        </ode>
      </friction>
      <bounce>
        <restitution_coefficient>0.01</restitution_coefficient>
        <threshold>10</threshold>
      </bounce>
      <contact>
        <ode>
          <max_vel>0.01</max_vel>
          <minDepth>0</minDepth>
          <contact_surface_layer>0</contact_surface_layer>
        </ode>
      </contact>
    </surface>
  </link>
  <link name="bottom_frame">
    <visual>
      <origin rpy="0 0 0" xyz="0 0 0"/>
      <geometry>
        <mesh filename="moby_rp/visual/Bottom_frame.stl"/>
      </geometry>
      <material name="metal_grey"/>
    </visual>
    <collision>
      <origin rpy="0 0 0" xyz="0 0 0"/>
      <geometry>
        <mesh filename="moby_rp/collision/Bottom_frame.stl"/>
      </geometry>
    </collision>
    <inertial>
      <mass value="48.9"/>
      <origin rpy="0 0 0" xyz="0.067079                             -7.7e-05                             -0.040652"/>
      <inertia ixx="2.354764" ixy="0.000253" ixz="0.133345" iyy="5.182793" iyz="-0.000153" izz="5.76203"/>
    </inertial>
    <surface>
      <friction>
        <ode>
          <mu>0.8</mu>
          <mu2>0.8</mu2>
          <kp>1e15</kp>
          <kd>1e13</kd>
        </ode>
      </friction>
      <bounce>
        <restitution_coefficient>0.01</restitution_coefficient>
        <threshold>10</threshold>
      </bounce>
      <contact>
        <ode>
          <max_vel>0.01</max_vel>
          <minDepth>0</minDepth>
          <contact_surface_layer>0</contact_surface_layer>
        </ode>
      </contact>
    </surface>
  </link>
  <link name="fl_rot_link">
    <visual>
      <origin rpy="0 0 0" xyz="0 0 0"/>
      <geometry>
        <mesh filename="moby_rp/visual/Left_rot_motor.stl"/>
      </geometry>
      <material name="metal_white"/>
    </visual>
    <collision>
      <origin rpy="0 0 0" xyz="0 0 0"/>
      <geometry>
        <mesh filename="moby_rp/collision/Left_rot_motor.stl"/>
      </geometry>
    </collision>
    <inertial>
      <mass value="4.06"/>
      <origin rpy="0 0 0" xyz="0.000459                             0.02447                             -0.067097"/>
      <inertia ixx="0.04595" ixy="-4.6e-05" ixz="0.000125" iyy="0.038956" iyz="0.006666" izz="0.01674"/>
    </inertial>
    <surface>
      <friction>
        <ode>
          <mu>0.8</mu>
          <mu2>0.8</mu2>
          <kp>1e15</kp>
          <kd>1e13</kd>
        </ode>
      </friction>
      <bounce>
        <restitution_coefficient>0.01</restitution_coefficient>
        <threshold>10</threshold>
      </bounce>
      <contact>
        <ode>
          <max_vel>0.01</max_vel>
          <minDepth>0</minDepth>
          <contact_surface_layer>0</contact_surface_layer>
        </ode>
      </contact>
    </surface>
  </link>
  <link name="fl_tract_link">
    <visual>
      <origin rpy="0 0 0" xyz="0 0 0"/>
      <geometry>
        <!-- <mesh filename="moby_rp/visual/Left_wheel.stl"/> -->
        <cylinder length="0.05" radius="0.1"/>
      </geometry>
      <material name="metal_grey"/>
    </visual>
    <collision>
      <origin rpy="0 0 0" xyz="0 0 0"/>
      <geometry>
        <!-- <mesh filename="moby_rp/collision/Left_wheel.stl"/> -->
        <cylinder length="0.05" radius="0.1"/>
      </geometry>
    </collision>
    <inertial>
      <mass value="11.076"/>
      <origin rpy="0 0 0" xyz="0.0                             -0.000162                             0.000717"/>
      <inertia ixx="0.049071" ixy="0.0" ixz="0.0" iyy="0.049071" iyz="1e-06" izz="0.07234"/>
    </inertial>
    <surface>
      <friction>
        <ode>
          <mu>0.8</mu>
          <mu2>0.8</mu2>
          <kp>1e15</kp>
          <kd>1e13</kd>
        </ode>
      </friction>
      <bounce>
        <restitution_coefficient>0.01</restitution_coefficient>
        <threshold>10</threshold>
      </bounce>
      <contact>
        <ode>
          <max_vel>0.01</max_vel>
          <minDepth>0</minDepth>
          <contact_surface_layer>0</contact_surface_layer>
        </ode>
      </contact>
    </surface>
  </link>
  <link name="fr_rot_link">
    <visual>
      <origin rpy="0 0 0" xyz="0 0 0"/>
      <geometry>
        <mesh filename="moby_rp/visual/Right_rot_motor.stl"/>
      </geometry>
      <material name="metal_white"/>
    </visual>
    <collision>
      <origin rpy="0 0 0" xyz="0 0 0"/>
      <geometry>
        <mesh filename="moby_rp/collision/Right_rot_motor.stl"/>
      </geometry>
    </collision>
    <inertial>
      <mass value="4.06"/>
      <origin rpy="0 0 0" xyz="0.000459                             0.02447                             -0.067097"/>
      <inertia ixx="0.04595" ixy="-4.6e-05" ixz="0.000125" iyy="0.038956" iyz="0.006666" izz="0.01674"/>
    </inertial>
    <surface>
      <friction>
        <ode>
          <mu>0.8</mu>
          <mu2>0.8</mu2>
          <kp>1e15</kp>
          <kd>1e13</kd>
        </ode>
      </friction>
      <bounce>
        <restitution_coefficient>0.01</restitution_coefficient>
        <threshold>10</threshold>
      </bounce>
      <contact>
        <ode>
          <max_vel>0.01</max_vel>
          <minDepth>0</minDepth>
          <contact_surface_layer>0</contact_surface_layer>
        </ode>
      </contact>
    </surface>
  </link>
  <link name="fr_tract_link">
    <visual>
      <origin rpy="0 0 0" xyz="0 0 0"/>
      <geometry>
        <!-- <mesh filename="moby_rp/visual/Right_wheel.stl"/> -->
        <cylinder length="0.05" radius="0.1"/>
      </geometry>
      <material name="metal_grey"/>
    </visual>
    <collision>
      <origin rpy="0 0 0" xyz="0 0 0"/>
      <geometry>
        <!-- <mesh filename="moby_rp/collision/Right_wheel.stl"/> -->
        <cylinder length="0.05" radius="0.1"/>
      </geometry>
    </collision>
    <inertial>
      <mass value="11.076"/>
      <origin rpy="0 0 0" xyz="0.0                             -0.000162                             0.000717"/>
      <inertia ixx="0.049071" ixy="0.0" ixz="0.0" iyy="0.049071" iyz="1e-06" izz="0.07234"/>
    </inertial>
    <surface>
      <friction>
        <ode>
          <mu>0.8</mu>
          <mu2>0.8</mu2>
          <kp>1e15</kp>
          <kd>1e13</kd>
        </ode>
      </friction>
      <bounce>
        <restitution_coefficient>0.01</restitution_coefficient>
        <threshold>10</threshold>
      </bounce>
      <contact>
        <ode>
          <max_vel>0.01</max_vel>
          <minDepth>0</minDepth>
          <contact_surface_layer>0</contact_surface_layer>
        </ode>
      </contact>
    </surface>
  </link>
  <link name="rl_rot_link">
    <visual>
      <origin rpy="0 0 0" xyz="0 0 0"/>
      <geometry>
        <mesh filename="moby_rp/visual/Left_rot_motor.stl"/>
      </geometry>
      <material name="metal_white"/>
    </visual>
    <collision>
      <origin rpy="0 0 0" xyz="0 0 0"/>
      <geometry>
        <mesh filename="moby_rp/collision/Left_rot_motor.stl"/>
      </geometry>
    </collision>
    <inertial>
      <mass value="4.06"/>
      <origin rpy="0 0 0" xyz="0.000459                             0.02447                             -0.067097"/>
      <inertia ixx="0.04595" ixy="-4.6e-05" ixz="0.000125" iyy="0.038956" iyz="0.006666" izz="0.01674"/>
    </inertial>
    <surface>
      <friction>
        <ode>
          <mu>0.8</mu>
          <mu2>0.8</mu2>
          <kp>1e15</kp>
          <kd>1e13</kd>
        </ode>
      </friction>
      <bounce>
        <restitution_coefficient>0.01</restitution_coefficient>
        <threshold>10</threshold>
      </bounce>
      <contact>
        <ode>
          <max_vel>0.01</max_vel>
          <minDepth>0</minDepth>
          <contact_surface_layer>0</contact_surface_layer>
        </ode>
      </contact>
    </surface>
  </link>
  <link name="rl_tract_link">
    <visual>
      <origin rpy="0 0 0" xyz="0 0 0"/>
      <geometry>
        <!-- <mesh filename="moby_rp/visual/Left_wheel.stl"/> -->
        <cylinder length="0.05" radius="0.1"/>
      </geometry>
      <material name="metal_grey"/>
    </visual>
    <collision>
      <origin rpy="0 0 0" xyz="0 0 0"/>
      <geometry>
        <!-- <mesh filename="moby_rp/collision/Left_wheel.stl"/> -->
        <cylinder length="0.05" radius="0.1"/>
      </geometry>
    </collision>
    <inertial>
      <mass value="11.076"/>
      <origin rpy="0 0 0" xyz="0.0                             -0.000162                             0.000717"/>
      <inertia ixx="0.049071" ixy="0.0" ixz="0.0" iyy="0.049071" iyz="1e-06" izz="0.07234"/>
    </inertial>
    <surface>
      <friction>
        <ode>
          <mu>0.8</mu>
          <mu2>0.8</mu2>
          <kp>1e15</kp>
          <kd>1e13</kd>
        </ode>
      </friction>
      <bounce>
        <restitution_coefficient>0.01</restitution_coefficient>
        <threshold>10</threshold>
      </bounce>
      <contact>
        <ode>
          <max_vel>0.01</max_vel>
          <minDepth>0</minDepth>
          <contact_surface_layer>0</contact_surface_layer>
        </ode>
      </contact>
    </surface>
  </link>
  <link name="rr_rot_link">
    <visual>
      <origin rpy="0 0 0" xyz="0 0 0"/>
      <geometry>
        <mesh filename="moby_rp/visual/Right_rot_motor.stl"/>
      </geometry>
      <material name="metal_white"/>
    </visual>
    <collision>
      <origin rpy="0 0 0" xyz="0 0 0"/>
      <geometry>
        <mesh filename="moby_rp/collision/Right_rot_motor.stl"/>
      </geometry>
    </collision>
    <inertial>
      <mass value="4.06"/>
      <origin rpy="0 0 0" xyz="0.000459                             0.02447                             -0.067097"/>
      <inertia ixx="0.04595" ixy="-4.6e-05" ixz="0.000125" iyy="0.038956" iyz="0.006666" izz="0.01674"/>
    </inertial>
    <surface>
      <friction>
        <ode>
          <mu>0.8</mu>
          <mu2>0.8</mu2>
          <kp>1e15</kp>
          <kd>1e13</kd>
        </ode>
      </friction>
      <bounce>
        <restitution_coefficient>0.01</restitution_coefficient>
        <threshold>10</threshold>
      </bounce>
      <contact>
        <ode>
          <max_vel>0.01</max_vel>
          <minDepth>0</minDepth>
          <contact_surface_layer>0</contact_surface_layer>
        </ode>
      </contact>
    </surface>
  </link>
  <link name="rr_tract_link">
    <visual>
      <origin rpy="0 0 0" xyz="0 0 0"/>
      <geometry>
        <!-- <mesh filename="moby_rp/visual/Right_wheel.stl"/> -->
        <cylinder length="0.05" radius="0.1"/>
      </geometry>
      <material name="metal_grey"/>
    </visual>
    <collision>
      <origin rpy="0 0 0" xyz="0 0 0"/>
      <geometry>
        <!-- <mesh filename="moby_rp/collision/Right_wheel.stl"/> -->
        <cylinder length="0.05" radius="0.1"/>
      </geometry>
    </collision>
    <inertial>
      <mass value="11.076"/>
      <origin rpy="0 0 0" xyz="0.0                             -0.000162                             0.000717"/>
      <inertia ixx="0.049071" ixy="0.0" ixz="0.0" iyy="0.049071" iyz="1e-06" izz="0.07234"/>
    </inertial>
    <surface>
      <friction>
        <ode>
          <mu>0.8</mu>
          <mu2>0.8</mu2>
          <kp>1e15</kp>
          <kd>1e13</kd>
        </ode>
      </friction>
      <bounce>
        <restitution_coefficient>0.01</restitution_coefficient>
        <threshold>10</threshold>
      </bounce>
      <contact>
        <ode>
          <max_vel>0.01</max_vel>
          <minDepth>0</minDepth>
          <contact_surface_layer>0</contact_surface_layer>
        </ode>
      </contact>
    </surface>
  </link>
  <link name="link0">
    <visual>
      <origin rpy="0 0 0" xyz="0 0 0"/>
      <geometry>
        <mesh filename="moby_rp/visual/Indy7_v2_0.stl"/>
      </geometry>
      <material name="metal_white"/>
    </visual>
    <collision>
      <origin rpy="0 0 0" xyz="0 0 0"/>
      <geometry>
        <mesh filename="moby_rp/collision/Indy7_v2_0.stl"/>
      </geometry>
    </collision>
    <inertial>
      <mass value="1.66957888"/>
      <origin rpy="0 0 0" xyz="0.00133032                             -2.18e-06                             0.03163661"/>
      <inertia ixx="0.00655829" ixy="1.83e-06" ixz="2.634e-05" iyy="0.00639165" iyz="-2.7e-07" izz="0.00791712"/>
    </inertial>
    <surface>
      <friction>
        <ode>
          <mu>0.8</mu>
          <mu2>0.8</mu2>
          <kp>1e15</kp>
          <kd>1e13</kd>
        </ode>
      </friction>
      <bounce>
        <restitution_coefficient>0.01</restitution_coefficient>
        <threshold>10</threshold>
      </bounce>
      <contact>
        <ode>
          <max_vel>0.01</max_vel>
          <minDepth>0</minDepth>
          <contact_surface_layer>0</contact_surface_layer>
        </ode>
      </contact>
    </surface>
  </link>
  <link name="link1">
    <visual>
      <origin rpy="0 0 0" xyz="0 0 0"/>
      <geometry>
        <mesh filename="moby_rp/visual/Indy7_v2_1.stl"/>
      </geometry>
      <material name="metal_white"/>
    </visual>
    <collision>
      <origin rpy="0 0 0" xyz="0 0 0"/>
      <geometry>
        <mesh filename="moby_rp/collision/Indy7_v2_1.stl"/>
      </geometry>
    </collision>
    <inertial>
      <mass value="11.43955917"/>
      <origin rpy="0 0 0" xyz="-0.00027386                             -0.04348767                             0.13216705"/>
      <inertia ixx="0.35097123" ixy="0.00013006" ixz="-0.00042705" iyy="0.3043588" iyz="-0.11072619" izz="0.06048047"/>
    </inertial>
    <surface>
      <friction>
        <ode>
          <mu>0.8</mu>
          <mu2>0.8</mu2>
          <kp>1e15</kp>
          <kd>1e13</kd>
        </ode>
      </friction>
      <bounce>
        <restitution_coefficient>0.01</restitution_coefficient>
        <threshold>10</threshold>
      </bounce>
      <contact>
        <ode>
          <max_vel>0.01</max_vel>
          <minDepth>0</minDepth>
          <contact_surface_layer>0</contact_surface_layer>
        </ode>
      </contact>
    </surface>
  </link>
  <link name="link2">
    <visual>
      <origin rpy="0 0 0" xyz="0 0 0"/>
      <geometry>
        <mesh filename="moby_rp/visual/Indy7_v2_2.stl"/>
      </geometry>
      <material name="metal_white"/>
    </visual>
    <collision>
      <origin rpy="0 0 0" xyz="0 0 0"/>
      <geometry>
        <mesh filename="moby_rp/collision/Indy7_v2_2.stl"/>
      </geometry>
    </collision>
    <inertial>
      <mass value="6.11383823"/>
      <origin rpy="0 0 0" xyz="-0.00010864                             0.29071865                             0.04588251"/>
      <inertia ixx="0.74655601" ixy="-0.00032714" ixz="4.81e-06" iyy="0.03850444" iyz="0.05314531" izz="0.72200046"/>
    </inertial>
    <surface>
      <friction>
        <ode>
          <mu>0.8</mu>
          <mu2>0.8</mu2>
          <kp>1e15</kp>
          <kd>1e13</kd>
        </ode>
      </friction>
      <bounce>
        <restitution_coefficient>0.01</restitution_coefficient>
        <threshold>10</threshold>
      </bounce>
      <contact>
        <ode>
          <max_vel>0.01</max_vel>
          <minDepth>0</minDepth>
          <contact_surface_layer>0</contact_surface_layer>
        </ode>
      </contact>
    </surface>
  </link>
  <link name="link3">
    <visual>
      <origin rpy="0 0 0" xyz="0 0 0"/>
      <geometry>
        <mesh filename="moby_rp/visual/Indy7_v2_3.stl"/>
      </geometry>
      <material name="metal_white"/>
    </visual>
    <collision>
      <origin rpy="0 0 0" xyz="0 0 0"/>
      <geometry>
        <mesh filename="moby_rp/collision/Indy7_v2_3.stl"/>
      </geometry>
    </collision>
    <inertial>
      <mass value="2.68211719"/>
      <origin rpy="0 0 0" xyz="6.691e-05                             -0.16802208                             -0.07025671"/>
      <inertia ixx="0.11373278" ixy="-3.686e-05" ixz="-1.286e-05" iyy="0.01627234" iyz="0.03355709" izz="0.10021441"/>
    </inertial>
    <surface>
      <friction>
        <ode>
          <mu>0.8</mu>
          <mu2>0.8</mu2>
          <kp>1e15</kp>
          <kd>1e13</kd>
        </ode>
      </friction>
      <bounce>
        <restitution_coefficient>0.01</restitution_coefficient>
        <threshold>10</threshold>
      </bounce>
      <contact>
        <ode>
          <max_vel>0.01</max_vel>
          <minDepth>0</minDepth>
          <contact_surface_layer>0</contact_surface_layer>
        </ode>
      </contact>
    </surface>
  </link>
  <link name="link4">
    <visual>
      <origin rpy="0 0 0" xyz="0 0 0"/>
      <geometry>
        <mesh filename="moby_rp/visual/Indy7_v2_4.stl"/>
      </geometry>
      <material name="metal_white"/>
    </visual>
    <collision>
      <origin rpy="0 0 0" xyz="0 0 0"/>
      <geometry>
        <mesh filename="moby_rp/collision/Indy7_v2_4.stl"/>
      </geometry>
    </collision>
    <inertial>
      <mass value="2.12830848"/>
      <origin rpy="0 0 0" xyz="-0.00026808                             -0.07105971                             0.07645329"/>
      <inertia ixx="0.02795227" ixy="3.938e-05" ixz="-4.713e-05" iyy="0.0143985" iyz="-0.01265087" izz="0.01495514"/>
    </inertial>
    <surface>
      <friction>
        <ode>
          <mu>0.8</mu>
          <mu2>0.8</mu2>
          <kp>1e15</kp>
          <kd>1e13</kd>
        </ode>
      </friction>
      <bounce>
        <restitution_coefficient>0.01</restitution_coefficient>
        <threshold>10</threshold>
      </bounce>
      <contact>
        <ode>
          <max_vel>0.01</max_vel>
          <minDepth>0</minDepth>
          <contact_surface_layer>0</contact_surface_layer>
        </ode>
      </contact>
    </surface>
  </link>
  <link name="link5">
    <visual>
      <origin rpy="0 0 0" xyz="0 0 0"/>
      <geometry>
        <mesh filename="moby_rp/visual/Indy7_v2_5.stl"/>
      </geometry>
      <material name="metal_white"/>
    </visual>
    <collision>
      <origin rpy="0 0 0" xyz="0 0 0"/>
      <geometry>
        <mesh filename="moby_rp/collision/Indy7_v2_5.stl"/>
      </geometry>
    </collision>
    <inertial>
      <mass value="2.32413397"/>
      <origin rpy="0 0 0" xyz="-0.00022538                             -0.00354123                             0.07650762"/>
      <inertia ixx="0.01771876" ixy="9.04e-06" ixz="-4.336e-05" iyy="0.01593616" iyz="-0.00069656" izz="0.00358348"/>
    </inertial>
    <surface>
      <friction>
        <ode>
          <mu>0.8</mu>
          <mu2>0.8</mu2>
          <kp>1e15</kp>
          <kd>1e13</kd>
        </ode>
      </friction>
      <bounce>
        <restitution_coefficient>0.01</restitution_coefficient>
        <threshold>10</threshold>
      </bounce>
      <contact>
        <ode>
          <max_vel>0.01</max_vel>
          <minDepth>0</minDepth>
          <contact_surface_layer>0</contact_surface_layer>
        </ode>
      </contact>
    </surface>
  </link>
  <link name="link6">
    <visual>
      <origin rpy="0 0 0" xyz="0 0 0"/>
      <geometry>
        <mesh filename="moby_rp/visual/Indy7_v2_6.stl"/>
      </geometry>
      <material name="metal_white"/>
    </visual>
    <collision>
      <origin rpy="0 0 0" xyz="0 0 0"/>
      <geometry>
        <mesh filename="moby_rp/collision/Indy7_v2_6.stl"/>
      </geometry>
    </collision>
    <inertial>
      <mass value="0.39652271"/>
      <origin rpy="0 0 0" xyz="0.0                             -0.00071501                             0.03219123"/>
      <inertia ixx="0.00077839" ixy="2.6e-07" ixz="0.0" iyy="0.00076561" iyz="-6.99e-06" izz="0.00051275"/>
    </inertial>
    <surface>
      <friction>
        <ode>
          <mu>0.8</mu>
          <mu2>0.8</mu2>
          <kp>1e15</kp>
          <kd>1e13</kd>
        </ode>
      </friction>
      <bounce>
        <restitution_coefficient>0.01</restitution_coefficient>
        <threshold>10</threshold>
      </bounce>
      <contact>
        <ode>
          <max_vel>0.01</max_vel>
          <minDepth>0</minDepth>
          <contact_surface_layer>0</contact_surface_layer>
        </ode>
      </contact>
    </surface>
  </link>
  <link name="tcp"/>
  <!-- JOINTS -->
  <joint name="footprint_joint" type="fixed">
    <parent link="base_footprint"/>
    <child link="base_link"/>
    <origin rpy="0                         0                         0" xyz="0.0                          0.0                          0.078818"/>
  </joint>
  <joint name="base_joint" type="fixed">
    <parent link="base_link"/>
    <child link="bottom_frame"/>
    <origin rpy="0                         0                         0" xyz="0                          0                          0.2"/>
  </joint>
  <joint name="frame_joint" type="fixed">
    <parent link="bottom_frame"/>
    <child link="top_frame"/>
    <origin rpy="0                         0                         0" xyz="0                          0                          0.2"/>
  </joint>
  <joint name="imu_joint" type="fixed">
    <parent link="base_link"/>
    <child link="imu_link"/>
    <origin rpy="0                         0                         0" xyz="0.183                          0                          0.21"/>
  </joint>
  <joint name="fl_rot_joint" type="revolute">
    <parent link="base_link"/>
    <child link="fl_rot_link"/>
    <origin rpy="0                         0                         0" xyz="0.393                          0.2054                          0.1704"/>
    <axis xyz="0 0 1"/>
    <dynamics damping="0.1" friction="10.0"/>
    <limit effort="60.0" lower="-3.141592653589793" upper="3.141592653589793" velocity="10.0"/>
  </joint>
  <joint name="fl_tract_joint" type="continuous">
    <parent link="fl_rot_link"/>
    <child link="fl_tract_link"/>
    <origin rpy="-1.570796327                         0                         0" xyz="0                          0                          -0.150218"/>
    <axis xyz="0 0 1"/>
    <dynamics damping="0.1" friction="10.0"/>
  </joint>
  <joint name="fr_rot_joint" type="revolute">
    <parent link="base_link"/>
    <child link="fr_rot_link"/>
    <origin rpy="0                         0                         0" xyz="0.393                          -0.2054                          0.1704"/>
    <axis xyz="0 0 1"/>
    <dynamics damping="0.1" friction="10.0"/>
    <limit effort="60.0" lower="-3.141592653589793" upper="3.141592653589793" velocity="10.0"/>
  </joint>
  <joint name="fr_tract_joint" type="continuous">
    <parent link="fr_rot_link"/>
    <child link="fr_tract_link"/>
    <origin rpy="-1.570796327                         0                         0" xyz="0                          0                          -0.150218"/>
    <axis xyz="0 0 1"/>
    <dynamics damping="0.1" friction="10.0"/>
  </joint>
  <joint name="rl_rot_joint" type="revolute">
    <parent link="base_link"/>
    <child link="rl_rot_link"/>
    <origin rpy="0                         0                         0" xyz="-0.393                          0.2054                          0.1704"/>
    <axis xyz="0 0 1"/>
    <dynamics damping="0.1" friction="10.0"/>
    <limit effort="60.0" lower="-3.141592653589793" upper="3.141592653589793" velocity="10.0"/>
  </joint>
  <joint name="rl_tract_joint" type="continuous">
    <parent link="rl_rot_link"/>
    <child link="rl_tract_link"/>
    <origin rpy="-1.570796327                         0                         0" xyz="0                          0                          -0.150218"/>
    <axis xyz="0 0 1"/>
    <dynamics damping="0.1" friction="10.0"/>
  </joint>
  <joint name="rr_rot_joint" type="revolute">
    <parent link="base_link"/>
    <child link="rr_rot_link"/>
    <origin rpy="0                         0                         0" xyz="-0.393                          -0.2054                          0.1704"/>
    <axis xyz="0 0 1"/>
    <dynamics damping="0.1" friction="10.0"/>
    <limit effort="60.0" lower="-3.141592653589793" upper="3.141592653589793" velocity="10.0"/>
  </joint>
  <joint name="rr_tract_joint" type="continuous">
    <parent link="rr_rot_link"/>
    <child link="rr_tract_link"/>
    <origin rpy="-1.570796327                         0                         0" xyz="0                          0                          -0.150218"/>
    <axis xyz="0 0 1"/>
    <dynamics damping="0.1" friction="10.0"/>
  </joint>
  <!-- camera body, with origin at bottom screw mount -->
  <joint name="front_camera_joint" type="fixed">
    <origin rpy="0                         0                         0" xyz="0.48515                          0                          0.2825"/>
    <parent link="base_link"/>
    <child link="front_camera_bottom_screw_frame"/>
  </joint>
  <link name="front_camera_bottom_screw_frame"/>
  <joint name="front_camera_link_joint" type="fixed">
    <origin rpy="0 0 0" xyz="0.010600000000000002 0.0175 0.0125"/>
    <parent link="front_camera_bottom_screw_frame"/>
    <child link="front_camera_link"/>
  </joint>
  <link name="front_camera_link">
    <visual>
      <!-- the mesh origin is at front plate in between the two infrared camera axes -->
      <origin rpy="1.5707963267948966 0 1.5707963267948966" xyz="0.0043 -0.0175 0"/>
      <geometry>
        <mesh filename="other_meshes/Realsense_d435.stl"/>
      </geometry>
      <material name="aluminum"/>
    </visual>
    <collision>
      <origin rpy="0 0 0" xyz="0 -0.0175 0"/>
      <geometry>
        <box size="0.02505 0.09 0.025"/>
      </geometry>
    </collision>
    <inertial>
      <!-- The following are not reliable values, and should not be used for modeling -->
      <mass value="0.072"/>
      <origin xyz="0 0 0"/>
      <inertia ixx="0.003881243" ixy="0.0" ixz="0.0" iyy="0.000498940" iyz="0.0" izz="0.003879257"/>
    </inertial>
  </link>
  <!-- camera body, with origin at bottom screw mount -->
  <joint name="rear_camera_joint" type="fixed">
    <origin rpy="0                         0                         3.1415926536" xyz="-0.48515                          0                          0.2825"/>
    <parent link="base_link"/>
    <child link="rear_camera_bottom_screw_frame"/>
  </joint>
  <link name="rear_camera_bottom_screw_frame"/>
  <joint name="rear_camera_link_joint" type="fixed">
    <origin rpy="0 0 0" xyz="0.010600000000000002 0.0175 0.0125"/>
    <parent link="rear_camera_bottom_screw_frame"/>
    <child link="rear_camera_link"/>
  </joint>
  <link name="rear_camera_link">
    <visual>
      <!-- the mesh origin is at front plate in between the two infrared camera axes -->
      <origin rpy="1.5707963267948966 0 1.5707963267948966" xyz="0.0043 -0.0175 0"/>
      <geometry>
        <mesh filename="other_meshes/Realsense_d435.stl"/>
      </geometry>
      <material name="aluminum"/>
    </visual>
    <collision>
      <origin rpy="0 0 0" xyz="0 -0.0175 0"/>
      <geometry>
        <box size="0.02505 0.09 0.025"/>
      </geometry>
    </collision>
    <inertial>
      <!-- The following are not reliable values, and should not be used for modeling -->
      <mass value="0.072"/>
      <origin xyz="0 0 0"/>
      <inertia ixx="0.003881243" ixy="0.0" ixz="0.0" iyy="0.000498940" iyz="0.0" izz="0.003879257"/>
    </inertial>
  </link>
  <!-- camera body, with origin at bottom screw mount -->
  <joint name="left_camera_joint" type="fixed">
    <origin rpy="0                         0                         1.570796327" xyz="0                          0.28505                          0.2825"/>
    <parent link="base_link"/>
    <child link="left_camera_bottom_screw_frame"/>
  </joint>
  <link name="left_camera_bottom_screw_frame"/>
  <joint name="left_camera_link_joint" type="fixed">
    <origin rpy="0 0 0" xyz="0.010600000000000002 0.0175 0.0125"/>
    <parent link="left_camera_bottom_screw_frame"/>
    <child link="left_camera_link"/>
  </joint>
  <link name="left_camera_link">
    <visual>
      <!-- the mesh origin is at front plate in between the two infrared camera axes -->
      <origin rpy="1.5707963267948966 0 1.5707963267948966" xyz="0.0043 -0.0175 0"/>
      <geometry>
        <mesh filename="other_meshes/Realsense_d435.stl"/>
      </geometry>
      <material name="aluminum"/>
    </visual>
    <collision>
      <origin rpy="0 0 0" xyz="0 -0.0175 0"/>
      <geometry>
        <box size="0.02505 0.09 0.025"/>
      </geometry>
    </collision>
    <inertial>
      <!-- The following are not reliable values, and should not be used for modeling -->
      <mass value="0.072"/>
      <origin xyz="0 0 0"/>
      <inertia ixx="0.003881243" ixy="0.0" ixz="0.0" iyy="0.000498940" iyz="0.0" izz="0.003879257"/>
    </inertial>
  </link>
  <!-- camera body, with origin at bottom screw mount -->
  <joint name="right_camera_joint" type="fixed">
    <origin rpy="0                         0                         -1.570796327" xyz="0                          -0.28505                          0.2825"/>
    <parent link="base_link"/>
    <child link="right_camera_bottom_screw_frame"/>
  </joint>
  <link name="right_camera_bottom_screw_frame"/>
  <joint name="right_camera_link_joint" type="fixed">
    <origin rpy="0 0 0" xyz="0.010600000000000002 0.0175 0.0125"/>
    <parent link="right_camera_bottom_screw_frame"/>
    <child link="right_camera_link"/>
  </joint>
  <link name="right_camera_link">
    <visual>
      <!-- the mesh origin is at front plate in between the two infrared camera axes -->
      <origin rpy="1.5707963267948966 0 1.5707963267948966" xyz="0.0043 -0.0175 0"/>
      <geometry>
        <mesh filename="other_meshes/Realsense_d435.stl"/>
      </geometry>
      <material name="aluminum"/>
    </visual>
    <collision>
      <origin rpy="0 0 0" xyz="0 -0.0175 0"/>
      <geometry>
        <box size="0.02505 0.09 0.025"/>
      </geometry>
    </collision>
    <inertial>
      <!-- The following are not reliable values, and should not be used for modeling -->
      <mass value="0.072"/>
      <origin xyz="0 0 0"/>
      <inertia ixx="0.003881243" ixy="0.0" ixz="0.0" iyy="0.000498940" iyz="0.0" izz="0.003879257"/>
    </inertial>
  </link>
  <joint name="front_lidar_joint" type="fixed">
    <origin rpy="3.1415926536                         0                         -0.7853981634" xyz="0.457001                          -0.257001                          0.2794"/>
    <parent link="base_link"/>
    <child link="front_lidar_mount"/>
  </joint>
  <link name="front_lidar_mount">
    <visual>
      <origin rpy="0 0 0" xyz="0 0 0"/>
      <geometry>
        <mesh filename="other_meshes/Sick_Tim771S.stl"/>
      </geometry>
      <material name="grey"/>
    </visual>
    <collision>
      <origin rpy="0 0 0" xyz="0 0 0"/>
      <geometry>
        <box size="0.06 0.06 0.08"/>
      </geometry>
    </collision>
    <inertial>
      <mass value="0.2"/>
      <!-- The following are not reliable values, and should not be used for modeling -->
      <origin xyz="0 0 0"/>
      <inertia ixx="0.003881243" ixy="0.0" ixz="0.0" iyy="0.000498940" iyz="0.0" izz="0.003879257"/>
    </inertial>
  </link>
  <joint name="front_lidar_link_joint" type="fixed">
    <origin rpy="0 0 0" xyz="0 0 0.06246"/>
    <parent link="front_lidar_mount"/>
    <child link="front_lidar_link"/>
  </joint>
  <link name="front_lidar_link"/>
  <joint name="rear_lidar_joint" type="fixed">
    <origin rpy="3.1415926536                         0                         2.35619449019" xyz="-0.457001                          0.257001                          0.2794"/>
    <parent link="base_link"/>
    <child link="rear_lidar_mount"/>
  </joint>
  <link name="rear_lidar_mount">
    <visual>
      <origin rpy="0 0 0" xyz="0 0 0"/>
      <geometry>
        <mesh filename="other_meshes/Sick_Tim771S.stl"/>
      </geometry>
      <material name="grey"/>
    </visual>
    <collision>
      <origin rpy="0 0 0" xyz="0 0 0"/>
      <geometry>
        <box size="0.06 0.06 0.08"/>
      </geometry>
    </collision>
    <inertial>
      <mass value="0.2"/>
      <!-- The following are not reliable values, and should not be used for modeling -->
      <origin xyz="0 0 0"/>
      <inertia ixx="0.003881243" ixy="0.0" ixz="0.0" iyy="0.000498940" iyz="0.0" izz="0.003879257"/>
    </inertial>
  </link>
  <joint name="rear_lidar_link_joint" type="fixed">
    <origin rpy="0 0 0" xyz="0 0 0.06246"/>
    <parent link="rear_lidar_mount"/>
    <child link="rear_lidar_link"/>
  </joint>
  <link name="rear_lidar_link"/>
  <joint name="base_arm" type="fixed">
    <parent link="base_link"/>
    <child link="link0"/>
    <origin rpy="0                         0                         0" xyz="0.3701                          0                          0.4455"/>
  </joint>
  <joint name="joint0" type="revolute">
    <parent link="link0"/>
    <child link="link1"/>
    <origin rpy="0                         0                         0" xyz="0                          0                          0.0775"/>
    <axis xyz="0 0 1"/>
    <dynamics damping="0.1" friction="10.0"/>
    <limit effort="431.97" lower="-3.0543261909900767" upper="3.0543261909900767" velocity="2.6179938779914944"/>
  </joint>
  <joint name="joint1" type="revolute">
    <parent link="link1"/>
    <child link="link2"/>
    <origin rpy="1.570796327                         0                         0" xyz="0                          -0.109                          0.222"/>
    <axis xyz="0 0 1"/>
    <dynamics damping="0.1" friction="10.0"/>
    <limit effort="431.97" lower="-3.0543261909900767" upper="3.0543261909900767" velocity="2.6179938779914944"/>
  </joint>
  <joint name="joint2" type="revolute">
    <parent link="link2"/>
    <child link="link3"/>
    <origin rpy="0                         0                         3.1415926536" xyz="0                          0.45                          -0.0305"/>
    <axis xyz="0 0 1"/>
    <dynamics damping="0.1" friction="10.0"/>
    <limit effort="197.23" lower="-3.0543261909900767" upper="3.0543261909900767" velocity="2.6179938779914944"/>
  </joint>
  <joint name="joint3" type="revolute">
    <parent link="link3"/>
    <child link="link4"/>
    <origin rpy="-1.570796327                         0                         3.1415926536" xyz="0                          -0.267                          -0.075"/>
    <axis xyz="0 0 1"/>
    <dynamics damping="0.1" friction="10.0"/>
    <limit effort="79.79" lower="-3.0543261909900767" upper="3.0543261909900767" velocity="3.141592653589793"/>
  </joint>
  <joint name="joint4" type="revolute">
    <parent link="link4"/>
    <child link="link5"/>
    <origin rpy="1.570796327                         0                         0" xyz="0                          -0.114                          0.0835"/>
    <axis xyz="0 0 1"/>
    <dynamics damping="0.1" friction="10.0"/>
    <limit effort="79.79" lower="-3.0543261909900767" upper="3.0543261909900767" velocity="3.141592653589793"/>
  </joint>
  <joint name="joint5" type="revolute">
    <parent link="link5"/>
    <child link="link6"/>
    <origin rpy="-1.570796327                         0                         0" xyz="0                          0.052                          0.085"/>
    <axis xyz="0 0 1"/>
    <dynamics damping="0.1" friction="10.0"/>
    <limit effort="79.79" lower="-3.7524578917878086" upper="3.7524578917878086" velocity="3.141592653589793"/>
  </joint>
  <joint name="joint_tcp" type="fixed">
    <parent link="link6"/>
    <child link="tcp"/>
    <origin rpy="0.0                         0.0                         0.0" xyz="0.0                          0.0                          0.06"/>
  </joint>
  <ros2_control name="moby" type="system">
    <hardware>
      <plugin>fake_components/GenericSystem</plugin>
      <param name="state_following_offset">0.0</param>
    </hardware>
    <!-- <xacro:if value="${moby_type == 'moby_agri'}"> NOT SUPPORT AGRI
                <xacro:define_control_joint joint_index="right_tract_joint"/>
                <xacro:define_control_joint joint_index="left_tract_joint"/>
                <xacro:define_control_joint joint_index="camera_module_joint"/>
            </xacro:if> -->
    <joint name="fl_rot_joint">
      <command_interface name="position">
        <param name="min">-6.283185</param>
        <param name="max">6.283185</param>
      </command_interface>
      <command_interface name="velocity">
        <param name="min">-3.141592</param>
        <param name="max">3.141592</param>
      </command_interface>
      <state_interface name="position">
        <param name="initial_value">0.000000</param>
      </state_interface>
      <state_interface name="velocity">
        <param name="initial_value">0.000000</param>
      </state_interface>
      <state_interface name="effort"/>
    </joint>
    <joint name="fr_rot_joint">
      <command_interface name="position">
        <param name="min">-6.283185</param>
        <param name="max">6.283185</param>
      </command_interface>
      <command_interface name="velocity">
        <param name="min">-3.141592</param>
        <param name="max">3.141592</param>
      </command_interface>
      <state_interface name="position">
        <param name="initial_value">0.000000</param>
      </state_interface>
      <state_interface name="velocity">
        <param name="initial_value">0.000000</param>
      </state_interface>
      <state_interface name="effort"/>
    </joint>
    <joint name="rl_rot_joint">
      <command_interface name="position">
        <param name="min">-6.283185</param>
        <param name="max">6.283185</param>
      </command_interface>
      <command_interface name="velocity">
        <param name="min">-3.141592</param>
        <param name="max">3.141592</param>
      </command_interface>
      <state_interface name="position">
        <param name="initial_value">0.000000</param>
      </state_interface>
      <state_interface name="velocity">
        <param name="initial_value">0.000000</param>
      </state_interface>
      <state_interface name="effort"/>
    </joint>
    <joint name="rr_rot_joint">
      <command_interface name="position">
        <param name="min">-6.283185</param>
        <param name="max">6.283185</param>
      </command_interface>
      <command_interface name="velocity">
        <param name="min">-3.141592</param>
        <param name="max">3.141592</param>
      </command_interface>
      <state_interface name="position">
        <param name="initial_value">0.000000</param>
      </state_interface>
      <state_interface name="velocity">
        <param name="initial_value">0.000000</param>
      </state_interface>
      <state_interface name="effort"/>
    </joint>
    <joint name="fl_tract_joint">
      <command_interface name="velocity">
        <param name="min">-9.424778</param>
        <!--3pi-->
        <param name="max">9.424778</param>
      </command_interface>
      <state_interface name="position"/>
      <state_interface name="velocity">
        <param name="initial_value">0.000000</param>
      </state_interface>
      <state_interface name="effort"/>
    </joint>
    <joint name="fr_tract_joint">
      <command_interface name="velocity">
        <param name="min">-9.424778</param>
        <!--3pi-->
        <param name="max">9.424778</param>
      </command_interface>
      <state_interface name="position"/>
      <state_interface name="velocity">
        <param name="initial_value">0.000000</param>
      </state_interface>
      <state_interface name="effort"/>
    </joint>
    <joint name="rl_tract_joint">
      <command_interface name="velocity">
        <param name="min">-9.424778</param>
        <!--3pi-->
        <param name="max">9.424778</param>
      </command_interface>
      <state_interface name="position"/>
      <state_interface name="velocity">
        <param name="initial_value">0.000000</param>
      </state_interface>
      <state_interface name="effort"/>
    </joint>
    <joint name="rr_tract_joint">
      <command_interface name="velocity">
        <param name="min">-9.424778</param>
        <!--3pi-->
        <param name="max">9.424778</param>
      </command_interface>
      <state_interface name="position"/>
      <state_interface name="velocity">
        <param name="initial_value">0.000000</param>
      </state_interface>
      <state_interface name="effort"/>
    </joint>
    <joint name="joint0">
      <command_interface name="position">
        <param name="min">-6.283185</param>
        <param name="max">6.283185</param>
      </command_interface>
      <command_interface name="velocity">
        <param name="min">-3.141592</param>
        <param name="max">3.141592</param>
      </command_interface>
      <!-- <state_interface name="position"/> -->
      <state_interface name="position">
        <param name="initial_value">0.0</param>
      </state_interface>
      <!-- <state_interface name="velocity"/> -->
      <state_interface name="velocity">
        <param name="initial_value">0.000000</param>
      </state_interface>
      <state_interface name="effort"/>
    </joint>
    <joint name="joint1">
      <command_interface name="position">
        <param name="min">-6.283185</param>
        <param name="max">6.283185</param>
      </command_interface>
      <command_interface name="velocity">
        <param name="min">-3.141592</param>
        <param name="max">3.141592</param>
      </command_interface>
      <!-- <state_interface name="position"/> -->
      <state_interface name="position">
        <param name="initial_value">0.5</param>
      </state_interface>
      <!-- <state_interface name="velocity"/> -->
      <state_interface name="velocity">
        <param name="initial_value">0.000000</param>
      </state_interface>
      <state_interface name="effort"/>
    </joint>
    <joint name="joint2">
      <command_interface name="position">
        <param name="min">-6.283185</param>
        <param name="max">6.283185</param>
      </command_interface>
      <command_interface name="velocity">
        <param name="min">-3.141592</param>
        <param name="max">3.141592</param>
      </command_interface>
      <!-- <state_interface name="position"/> -->
      <state_interface name="position">
        <param name="initial_value">-2.0</param>
      </state_interface>
      <!-- <state_interface name="velocity"/> -->
      <state_interface name="velocity">
        <param name="initial_value">0.000000</param>
      </state_interface>
      <state_interface name="effort"/>
    </joint>
    <joint name="joint3">
      <command_interface name="position">
        <param name="min">-6.283185</param>
        <param name="max">6.283185</param>
      </command_interface>
      <command_interface name="velocity">
        <param name="min">-3.141592</param>
        <param name="max">3.141592</param>
      </command_interface>
      <!-- <state_interface name="position"/> -->
      <state_interface name="position">
        <param name="initial_value">0.0</param>
      </state_interface>
      <!-- <state_interface name="velocity"/> -->
      <state_interface name="velocity">
        <param name="initial_value">0.000000</param>
      </state_interface>
      <state_interface name="effort"/>
    </joint>
    <joint name="joint4">
      <command_interface name="position">
        <param name="min">-6.283185</param>
        <param name="max">6.283185</param>
      </command_interface>
      <command_interface name="velocity">
        <param name="min">-3.141592</param>
        <param name="max">3.141592</param>
      </command_interface>
      <!-- <state_interface name="position"/> -->
      <state_interface name="position">
        <param name="initial_value">-1.7</param>
      </state_interface>
      <!-- <state_interface name="velocity"/> -->
      <state_interface name="velocity">
        <param name="initial_value">0.000000</param>
      </state_interface>
      <state_interface name="effort"/>
    </joint>
    <joint name="joint5">
      <command_interface name="position">
        <param name="min">-6.283185</param>
        <param name="max">6.283185</param>
      </command_interface>
      <command_interface name="velocity">
        <param name="min">-3.141592</param>
        <param name="max">3.141592</param>
      </command_interface>
      <!-- <state_interface name="position"/> -->
      <state_interface name="position">
        <param name="initial_value">0.0</param>
      </state_interface>
      <!-- <state_interface name="velocity"/> -->
      <state_interface name="velocity">
        <param name="initial_value">0.000000</param>
      </state_interface>
      <state_interface name="effort"/>
    </joint>
  </ros2_control>
</robot>
